Workbook

Sheet Supp. info
B1: Supporting Information
B3: Functional Centralization, Congestion, and Tailpipe Emissions: Evidence from Yaoundé, Cameroon
B4: Anehmbom Ghoutum 1,2, Nkweauseh Reginald Longfor2*, Aloysious Kohtem Lebga1, John Joseph Puthenkalam2, Xuepeng Qian2
B5: 1 National Institute of Cartography, Yaoundé, Cameroon
B6: 2 Graduate School of Global Environmental Studies, Sophia University, Tokyo, Japan
B8: * Corresponding author: NKWEAUSEH REGINALD LONGFOR. Email: n-longfor-3r2@sophia.ac.jp
B10: Attached you may find the numerical results from the traffic volume analysis, tailpipe emissions estimations (tier 1 and 2), congestion penalties, missed trips and economic impact on driver and passenger

Sheet Sat. City Pop.
B2: Satellite town population density estimation
B4: Satellite Town | C4: Road network length (km) | D4: Surface Area (km2) | E4: Population | F4: Road network density (km/km2) | G4: Population density (Pop/km2)
B5: Soa | C5: 670.9 | D5: 68 | E5: 86150 | F5: =C5/D5 -> 9.8661765 | G5: =E5/D5 -> 1266.9118
B6: Mbankomo | C6: 295.1 | D6: 40.8 | E6: 49755 | F6: =C6/D6 -> 7.2328431 | G6: =E6/D6 -> 1219.4853
B7: Mfou | C7: 204.8 | D7: 80.2 | E7: 91045 | F7: =C7/D7 -> 2.553616 | G7: =E7/D7 -> 1135.2244

Sheet Vehicle Infos
A2: Vehicle Information | K2: Tier 1 | L2: Tier 2
B3: Brand Name | C3: Model | D3: Engine capacity (cm3) | E3: Horsepower (CV) | F3: Energy Source | G3: Engine type | H3: Date of first use | I3: Fuel efficiency (litres/100km) | J3: Fuel mileage (km/L) | K3: Engine emission factor (kgCO2/liter) | L3: Engine emission factor (kgCO2/km) | N3: Reference
A4: SOA | B4: Toyota | C4: HIACE 21JK12 | D4: 2494 | E4: 10 | F4: Gas | G4: Diesel | H4: 17/05/1997 | I4: 10.7 | J4: 9.35 | K4: 3.18 | L4: 0.271743 | M4: Diesel large: Euro 2 | N4: https://motoreu.com/toyota-hiace-combi-2.5-d-4d-mpg-fuel-consumption-technical-specifications-174601
C5: HIACE 4XD | D5: 2446 | E5: 8 | F5: Gas | G5: Diesel | H5: 10/02/2000 | I5: 12.1 | J5: 9.8 | K5: 3.18 | L5: 0.24523 | M5: Diesel large: Euro 3 | N5: https://www.carsales.com.au/research/toyota/hiace/2000/
C6: BB42L-BRMRS | D6: 3661 | E6: 10 | F6: Gas | G6: Diesel | H6: 43313 | I6: 12.5 | J6: 8.8 | K6: 3.18 | L6: 0.231132 | M6: Diesel large: Euro 6 a/b/c | N6: https://www.fosterstoyota.com/blog/toyota-coaster-4-2l-diesel-1737809279010
B7: Mercedes | C7: MB100D 631334 | D7: 2399 | E7: 8 | F7: Gas | G7: Diesel | H7: 25/01/1994 | I7: 9.9 | J7: 10 | K7: 3.18 | L7: 0.262608 | M7: Diesel large: Euro 1 | N7: https://www.youtube.com/watch?v=Prxw5jUTpp4
C8: Sprinter 904663 | D8: 2300 | E8: 9 | F8: Gas | G8: Diesel | H8: 36162 | I8: 9.81 | J8: 10.2 | K8: 3.18 | L8: 0.271743 | M8: Diesel large: Euro 2 | N8: https://www.spritmonitor.de/en/detail/390169.html?page=2
C9: 207 | D9: 2399 | E9: 8 | F9: Gas | G9: Diesel | H9: 29/09/1993 | I9: 13.6 | J9: 7.3 | K9: 3.18 | L9: 0.262608 | M9: Diesel large: Euro 1 | N9: https://www.spritmonitor.de/en/detail/281441.html?cdetail=1
H10: Average | I10: =AVERAGE(I4:I9) -> 11.435 | J10: =AVERAGE(J4:J9) -> 9.2416667 | K10: =AVERAGE(K4:K9) -> 3.18 | L10: =AVERAGE(L4:L9) -> 0.25751067
A13: MFOU | B13: Toyota | C13: 64ABK | D13: 1587 | E13: 9 | F13: Petrol | G13: Diesel | H13: 10/05/1997 | K13: 3.168 | L13: 0.170121 | M13: Petrol small: Euro 2
C14: 52EP82 | D14: 1295 | E14: 7 | F14: Petrol | G14: Diesel | H14: 01/01/1993 | I14: 15 | K14: 3.168 | L14: 0.173288 | M14: Petrol small: Euro 1 | N14: https://www.pakwheels.com/new-cars/toyota/starlet/fuel-average/ | O14: http://www.demoporto.com/images/provas/2019/RampaPenha/3-Resultados/CPM/09-%20Tempos%20Subida%20Oficial%203%20CPM.pdf | P14: https://www.pakwheels.com/new-cars/toyota/starlet/1-3--2/
C15: 53ABNO | D15: 1587 | E15: 7 | F15: Petrol | G15: Diesel | H15: 20/10/2000 | I15: 9.7 | K15: 3.168 | L15: 0.174866 | M15: Petrol small: Euro 3 | N15: https://podbor.ravenol.ru/1-cars/535-toyota/2206-avensis-t22/6163-avensis-1-6/ | O15: https://www.auto-data.net/en/toyota-avensis-hatch-t22-1.6-101hp-3610
C16: YARIS VVT-I | D16: 998 | E16: 6 | F16: Petrol | G16: Diesel | H16: 22/09/2004 | I16: 6.4 | K16: 3.168 | L16: 0.174866 | M16: Petrol mini: Euro 3 | N16: https://car-emissions.com/cars/view/11408
C17: NCP92L | D17: 1299 | E17: 7 | F17: Petrol | G17: Diesel | H17: 01/01/2007 | I17: 6.7 | K17: 3.168 | L17: 0.182336 | M17: Petrol small: Euro 5 | N17: https://www.carsales.com.au/research/toyota/yaris/2007/
C18: KSP902 | D18: 998 | E18: 6 | F18: Petrol | G18: Diesel | H18: 01/01/2007 | I18: 24.5 | K18: 3.168 | L18: 0.182336 | M18: Petrol mini: Euro 5 | N18: https://cars.japanesecartrade.com/detail/toyota/vitz/b-intelligent-package/131468 | O18: 996cc
C19: AVENSIS GH22B2 | D19: 1998 | E19: 11 | F19: Petrol | G19: Diesel | H19: 31/03/2005 | I19: 12.8 | K19: 3.168 | L19: 0.214905 | M19: Petrol medium: Euro 4 | N19: weight difference | O19: https://www.autoevolution.com/cars/toyota-avensis-2003.html#aeng_toyota-avensis-2003-20-vvti-4at-147-hp
B20: Mercedes | C20: 240D123 | D20: 3690 | E20: 15 | F20: Gas | G20: Diesel | H20: 24/07/2001 | K20: 3.18 | O20: https://www.spritmonitor.de/en/detail/797414.html?cdetail=1
I21: =AVERAGE(I13:I19) -> 12.516667 | K21: =AVERAGE(K13:K20) -> 3.1695 | L21: =AVERAGE(L13:L19) -> 0.18181686
A23: MBANKOMO | B23: Toyota | C23: 53ABNO | D23: 1587 | E23: 9 | F23: Petrol | G23: Diesel | H23: 26/01/2001 | I23: 10.8 | K23: 3.168 | L23: 0.174866 | M23: Petrol small: Euro 3 | N23: https://www.ultimatespecs.com/car-specs/Toyota/5193/Toyota-Avensis-I-16.html
C24: 64ZBN1 | D24: 1794 | E24: 10 | F24: Petrol | G24: Diesel | H24: 31/01/2001 | I24: 7.4 | K24: 3.168 | L24: 0.174866 | M24: Petrol small: Euro 3 | N24: https://choise.ravenol.com/1-cars/535-toyota/2206-avensis-t22/6166-avensis-1-8-16v-vtt-i/ | O24: https://www.engineindetail.com/pa/toyota-avensis-liftback-1-8-style-2001
C25: COROLLA VVT-1 | D25: 1398 | E25: 8 | F25: Petrol | G25: Diesel | H25: 01/01/1999 | I25: 8.9 | K25: 3.168 | L25: 0.170121 | M25: Petrol small: Euro 2 | N25: https://www.ultimatespecs.com/car-specs/Toyota/5296/Toyota-Corolla-VIII-5-door-14-16v-VVT-i.html
C26: EE90 | D26: 1332 | E26: 7 | F26: Petrol | G26: Diesel | H26: 01/01/1990 | I26: 9.04 | K26: 3.168 | L26: 0.173288 | M26: Petrol small: Euro 1 | N26: https://www.spritmonitor.de/en/detail/393752.html?cdetail=1 | O26: https://www.careka.lk/en/vehicle/toyota-corolla-ee90-1990-4 | P26: https://www.beforward.jp/toyota/corolla-sedan/bf163753/id/159049/
C27: KV123 | D27: 998 | E27: 6 | F27: Petrol | G27: Diesel | H27: 09/07/1999 | K27: 3.168 | L27: 0.1547 | M27: Petrol mini: Euro 2 | N27: https://www.facebook.com/story.php/?story_fbid=367416665933900&id=100079967086663&_rdr
C28: YARIS VVT-I | D28: 998 | E28: 6 | F28: Petrol | G28: Diesel | H28: 22/09/2004 | I28: 6.8 | K28: 3.168 | L28: 0.1547 | M28: Petrol mini: Euro 4 | N28: https://car-emissions.com/cars/view/11407 | O28: https://www.emissionsfinder.com/toyota-yaris-10-vvt-i-10cc-3
I29: =AVERAGE(I23:I28) -> 8.588 | K29: =AVERAGE(K23:K28) -> 3.168 | L29: =AVERAGE(L23:L28) -> 0.16709017
D34: Total distance | E34: Distance covered x round trip x trips per month
D35: Fuel consumption | E35: Total distance x fuel efficiency

Sheet Monday Est.
B2: Monday Tailpipe Emissions | D2: Soa | F2: Mfou | G2: Mbankomo
B3: Fuel consumed on total stretch | C3: Toyota | D3: 2.5 | F3: 3.3 | G3: 2.5 | H3: litres | I3: Information from driver interview
C4: Mercedes | D4: 3 | H4: litres
B5: Number of buses | C5: Time frame | D5: Number of Vehicles
C6: 06:00 - 07:00 | D6: =30+14 -> 44 | F6: 19 | G6: 13
C7: 07:00 - 10:00 | D7: =144+69 -> 213 | F7: 78 | G7: 65
C8: 10:00 - 15:00 | D8: =224+180 -> 404 | F8: 91 | G8: 61
C9: 15:00 - 19:00 | D9: =128+86 -> 214 | F9: 88 | G9: 39
C10: 19:00 - 22:00 | D10: =124+66 -> 190 | F10: 34 | G10: 31
C11: Number of days in a year | D11: 365
C14: 6:00-7:00 Scenario | H14: Tail Pipe Emissions | L14: Monday 6:00-7:00 Scenario | Q14: Tail Pipe Emissions | U14: Monday 6:00-7:00 Scenario
B15: Road Network Stretches | C15: Soa-Yaounde | D15: Cummulative distance (Km) | E15: Distance per stretch (km) | F15: Clock Time (mins) | G15: Average time Taken (min) | H15: Tier 1 Emissions (kg CO2) (Daily) | I15: Tier 2 Emissions (kg CO2) (Daily) | L15: Mfou-Yaounde | M15: Cummulative distance (Km) | N15: Distance per stretch | O15: Clock Time | P15: Average time Taken (min) | Q15: Tier 1 Emissions (kg CO2) (Daily) | R15: Tier 2 Emissions (kg CO2) (Daily) | U15: Mbankomo-Yaounde | V15: Cummulative distance (Km) | W15: Distance per stretch | X15: Clock Time | Y15: Average time Taken (min) | Z15: Tier 1 Emissions (kg CO2) (Daily) | AA15: Tier 2 Emissions (kg CO2) (Daily)
C16: Soa Centre | D16: 0 | E16: 0 | F16: 6:00 | G16: 0 | H16: =D6*D3*'Vehicle Infos'!K10 -> 349.8 | I16: =$D$6*'Monday Est.'!E16*'Vehicle Infos'!$L$10 -> 0 | L16: Marche Mfou | M16: 0 | N16: 0 | O16: 6:00 | P16: 0 | Q16: =F6*F3*'Vehicle Infos'!K21 -> 198.72765 | R16: =$F$6*'Monday Est.'!N16*'Vehicle Infos'!$L$21 -> 0 | U16: Green oil | V16: 0 | W16: 0 | X16: 6:00 | Y16: 0 | Z16: =G6*G3*'Vehicle Infos'!K29 -> 102.96 | AA16: =$G$6*'Monday Est.'!W16*'Vehicle Infos'!$L$29 -> 0
C17: Soa Centre -Vallée vert | D17: 7.5 | E17: 7.5 | F17: 6:07 | G17: 7 | I17: =$D$6*'Monday Est.'!E17*'Vehicle Infos'!$L$10 -> 84.97852 | L17: Marche Mfou - Gare Mfou | M17: 1 | N17: 1 | O17: 6:02 | P17: 2 | R17: =$F$6*'Monday Est.'!N17*'Vehicle Infos'!$L$21 -> 3.4545203 | U17: Green oil - Entrée Ngoumou | V17: 3 | W17: 3 | X17: 6:05 | Y17: 5 | AA17: =$G$6*'Monday Est.'!W17*'Vehicle Infos'!$L$29 -> 6.5165165
C18: Vallée vert -Petite marché | D18: 8 | E18: 0.5 | F18: 6:10 | G18: 3 | I18: =$D$6*'Monday Est.'!E18*'Vehicle Infos'!$L$10 -> 5.6652347 | L18: Gare Mfou - Gustave Eiffel | M18: 2.5 | N18: 1.5 | O18: 6:05 | P18: 3 | R18: =$F$6*'Monday Est.'!N18*'Vehicle Infos'!$L$21 -> 5.1817804 | U18: Entrée Ngoumou - Carrefour Nomayos | V18: 5.5 | W18: 2.5 | X18: 6:12 | Y18: 7 | AA18: =$G$6*'Monday Est.'!W18*'Vehicle Infos'!$L$29 -> 5.4304304
C19: Petite marché-Eleveur | D19: 9 | E19: 1 | F19: 6:14 | G19: 4 | I19: =$D$6*'Monday Est.'!E19*'Vehicle Infos'!$L$10 -> 11.330469 | L19: Gustave Eiffel - Entrée EP Meyo | M19: 9 | N19: 6.5 | O19: 6:14 | P19: 9 | R19: =$F$6*'Monday Est.'!N19*'Vehicle Infos'!$L$21 -> 22.454382 | U19: Carrefour Nomayos - Entrée CIMENCAM | V19: 7.5 | W19: 2 | X19: 6:19 | Y19: 7 | AA19: =$G$6*'Monday Est.'!W19*'Vehicle Infos'!$L$29 -> 4.3443443
C20: Eleveur-Total Ngoussou | D20: 10 | E20: 1 | F20: 6:18 | G20: 4 | I20: =$D$6*'Monday Est.'!E20*'Vehicle Infos'!$L$10 -> 11.330469 | L20: Entrée EP Meyo - Carrefour Nkongoa | M20: 12 | N20: 3 | O20: 6:19 | P20: 5 | R20: =$F$6*'Monday Est.'!N20*'Vehicle Infos'!$L$21 -> 10.363561 | U20: Entrée CIMENCAM - Barrier (Tradex Ahala) | V20: 12 | W20: 4.5 | X20: 6:35 | Y20: 16 | AA20: =$G$6*'Monday Est.'!W20*'Vehicle Infos'!$L$29 -> 9.7747748
C21: Total Ngoussou -Mobil Omnisport | D21: 11 | E21: 1 | F21: 6:26 | G21: 8 | I21: =$D$6*'Monday Est.'!E21*'Vehicle Infos'!$L$10 -> 11.330469 | L21: Carrefour Nkongoa - Carrefour Monti | M21: 15.5 | N21: 3.5 | O21: 6:24 | P21: 5 | R21: =$F$6*'Monday Est.'!N21*'Vehicle Infos'!$L$21 -> 12.090821 | U21: Total | W21: =SUM(W17:W20) -> 12 | Y21: =SUM(Y17:Y20) -> 35 | Z21: =SUM(Z16) -> 102.96 | AA21: =$G$6*'Monday Est.'!W21*'Vehicle Infos'!$L$29 -> 26.066066
C22: Mobil Omnisport -Texaco Omnisport | D22: 12 | E22: 1 | F22: 6:31 | G22: 5 | I22: =$D$6*'Monday Est.'!E22*'Vehicle Infos'!$L$10 -> 11.330469 | L22: Carrefour Monti - Hawai Escallier | M22: 18.5 | N22: 3 | O22: 6:30 | P22: 6 | R22: =$F$6*'Monday Est.'!N22*'Vehicle Infos'!$L$21 -> 10.363561
C23: Texaco Omnisport -Total Mfouda | D23: 14 | E23: 2 | F23: 6:38 | G23: 7 | I23: =$D$6*'Monday Est.'!E23*'Vehicle Infos'!$L$10 -> 22.660939 | L23: Total | N23: =SUM(N16:N22) -> 18.5 | P23: =SUM(P17:P22) -> 30 | Q23: =SUM(Q16) -> 198.72765 | R23: =$F$6*'Monday Est.'!N23*'Vehicle Infos'!$L$21 -> 63.908625
C24: Total Mfouda-Mobil Elig-Essono | D24: 14.5 | E24: 0.5 | F24: 6:41 | G24: 3 | I24: =$D$6*'Monday Est.'!E24*'Vehicle Infos'!$L$10 -> 5.6652347
C25: Mobil Elig-Essono-Camair | D25: 15 | E25: 0.5 | F25: 6:42 | G25: 1 | I25: =$D$6*'Monday Est.'!E25*'Vehicle Infos'!$L$10 -> 5.6652347
C26: Total | E26: 15 | G26: =SUM(G16:G25) -> 42 | H26: =SUM(H16) -> 349.8 | I26: =$D$6*'Monday Est.'!E26*'Vehicle Infos'!$L$10 -> 169.95704
AH27: Daily time coverage per stretch (Soa Centre - CAMAIR)
C28: 7:00-10:00 Scenario | L28: Monday 7:00-10:00 Scenario | U28: Monday 7:00-10:00 Scenario | AI28: 1 | AJ28: =10-7 -> 3 | AK28: =15-10 -> 5 | AL28: =19-15 -> 4 | AM28: =22-19 -> 3
C29: Soa-Yaounde: Road Network Stretches | D29: Cummulative distance (Km) | E29: Distance per stretch | F29: Clock Time | G29: Average time Taken (min) | H29: Tier 1 Emissions (kg CO2) (Daily) | I29: Tier 2 Emissions (kg CO2) (Daily) | L29: Mfou-Yaounde: Road Network Stretches | M29: Cummulative distance (Km) | N29: Distance per stretch | O29: Clock Time | P29: Average time Taken (min) | Q29: Tier 1 Emissions (kg CO2) (Daily) | R29: Tier 2 Emissions (kg CO2) (Daily) | U29: Mbankomo-Yaounde: Road Network Stretches | V29: Cummulative distance (Km) | W29: Distance per stretch | X29: Clock Time | Y29: Average time Taken (min) | Z29: Tier 1 Emissions (kg CO2) (Daily) | AA29: Tier 2 Emissions (kg CO2) (Daily) | AI29: 6:00 - 7:00 | AJ29: 7:00 - 10:00 | AK29: 10:00 - 15:00 | AL29: 15:00 - 19:00 | AM29: 19:00 - 22:00
C30: Soa Centre | D30: 0 | E30: 0 | F30: 7:30 | H30: =D7*D3*'Vehicle Infos'!K10 -> 1693.35 | I30: =$D$7*'Monday Est.'!E30*'Vehicle Infos'!$L$10 -> 0 | L30: Marche Mfou | M30: 0 | N30: 0 | O30: 8:00 | Q30: =F7*F3*'Vehicle Infos'!K21 -> 815.8293 | R30: =$F$7*'Monday Est.'!N30*'Vehicle Infos'!$L$21 -> 0 | U30: Green oil | V30: 0 | W30: 0 | X30: 7:00 | Y30: 0 | Z30: =G7*G3*'Vehicle Infos'!K29 -> 514.8 | AA30: =$G$7*'Monday Est.'!W30*'Vehicle Infos'!$L$29 -> 0 | AH30: Monday | AI30: =G26 -> 42 | AJ30: =G40 -> 62 | AK30: =G54 -> 36 | AL30: =G69 -> 66 | AM30: =G83 -> 56
C31: Soa Centre -Vallée vert | D31: 7.5 | E31: 7.5 | F31: 7:37 | G31: 7 | I31: =$D$7*'Monday Est.'!E31*'Vehicle Infos'!$L$10 -> 411.37329 | L31: Marche Mfou - Gare Mfou | M31: 1 | N31: 1 | O31: 8:02 | P31: 2 | R31: =$F$7*'Monday Est.'!N31*'Vehicle Infos'!$L$21 -> 14.181715 | U31: Green oil - Entrée Ngoumou | V31: 3 | W31: 3 | X31: 7:06 | Y31: 6 | AA31: =$G$7*'Monday Est.'!W31*'Vehicle Infos'!$L$29 -> 32.582583 | AH31: Tuesday | AI31: ='Tuesday Est.'!G41 -> 60 | AJ31: ='Tuesday Est.'!G56 -> 35 | AK31: ='Tuesday Est.'!G56 -> 35 | AL31: ='Tuesday Est.'!G71 -> 63 | AM31: ='Tuesday Est.'!G86 -> 51
C32: Vallée vert -Petite marché | D32: 8 | E32: 0.5 | F32: 7:4 | G32: 3 | I32: =$D$7*'Monday Est.'!E32*'Vehicle Infos'!$L$10 -> 27.424886 | L32: Gare Mfou - Gustave Eiffel | M32: 2.5 | N32: 1.5 | O32: 8:06 | P32: 3.5 | R32: =$F$7*'Monday Est.'!N32*'Vehicle Infos'!$L$21 -> 21.272572 | U32: Entrée Ngoumou - Carrefour Nomayos | V32: 5.5 | W32: 2.5 | X32: 7:14 | Y32: 8 | AA32: =$G$7*'Monday Est.'!W32*'Vehicle Infos'!$L$29 -> 27.152152 | AH32: Wednesday | AI32: ='Wednesday Est.'!G26 -> 37 | AJ32: ='Wednesday Est.'!G41 -> 60 | AK32: ='Wednesday Est.'!G56 -> 34 | AL32: ='Wednesday Est.'!G71 -> 61 | AM32: ='Tuesday Est.'!G86 -> 51
C33: Petite marché-Eleveur | D33: 9 | E33: 1 | F33: 7:48 | G33: 8 | I33: =$D$7*'Monday Est.'!E33*'Vehicle Infos'!$L$10 -> 54.849772 | L33: Gustave Eiffel - Entrée EP Meyo | M33: 9 | N33: 6.5 | O33: 8:15 | P33: 9 | R33: =$F$7*'Monday Est.'!N33*'Vehicle Infos'!$L$21 -> 92.181147 | U33: Carrefour Nomayos - Entrée CIMENCAM | V33: 7.5 | W33: 2 | X33: 7:26 | Y33: 12 | AA33: =$G$7*'Monday Est.'!W33*'Vehicle Infos'!$L$29 -> 21.721722 | AH33: Thursday | AI33: ='Thursday Est.'!G26 -> 36 | AJ33: ='Thursday Est.'!G41 -> 55 | AK33: ='Thursday Est.'!G56 -> 31 | AL33: ='Thursday Est.'!G71 -> 46 | AM33: ='Thursday Est.'!G86 -> 34
C34: Eleveur-Total Ngoussou | D34: 10 | E34: 1 | F34: 7:55 | G34: 7 | I34: =$D$7*'Monday Est.'!E34*'Vehicle Infos'!$L$10 -> 54.849772 | L34: Entrée EP Meyo - Carrefour Nkongoa | M34: 12 | N34: 3 | O34: 8:24 | P34: 9 | R34: =$F$7*'Monday Est.'!N34*'Vehicle Infos'!$L$21 -> 42.545145 | U34: Entrée CIMENCAM - Barrier (Tradex Ahala) | V34: 12 | W34: 4.5 | X34: 7:52 | Y34: 26 | AA34: =$G$7*'Monday Est.'!W34*'Vehicle Infos'!$L$29 -> 48.873874 | AH34: Friday | AI34: ='Friday Est'!G26 -> 30 | AJ34: ='Friday Est'!G41 -> 49 | AK34: ='Friday Est'!G56 -> 33 | AL34: ='Friday Est'!G71 -> 40 | AM34: ='Friday Est'!G86 -> 32
C35: Total Ngoussou -Mobil Omnisport | D35: 11 | E35: 1 | F35: 8:10 | G35: 15 | I35: =$D$7*'Monday Est.'!E35*'Vehicle Infos'!$L$10 -> 54.849772 | L35: Carrefour Nkongoa - Carrefour Monti | M35: 15.5 | N35: 3.5 | O35: 8:36 | P35: 12 | R35: =$F$7*'Monday Est.'!N35*'Vehicle Infos'!$L$21 -> 49.636002 | U35: Total | W35: =SUM(W31:W34) -> 12 | Y35: =SUM(Y31:Y34) -> 52 | Z35: =SUM(Z30) -> 514.8 | AA35: =$G$7*'Monday Est.'!W35*'Vehicle Infos'!$L$29 -> 130.33033 | AH35: Saturday | AI35: ='Saturday Est.'!G26 -> 33 | AJ35: ='Saturday Est.'!G42 -> 42 | AK35: ='Saturday Est.'!G58 -> 35 | AL35: ='Saturday Est.'!G74 -> 41 | AM35: ='Saturday Est.'!G90 -> 33
C36: Mobil Omnisport -Texaco Omnisport | D36: 12 | E36: 1 | F36: 8:16 | G36: 6 | I36: =$D$7*'Monday Est.'!E36*'Vehicle Infos'!$L$10 -> 54.849772 | L36: Carrefour Monti - Hawai Escallier | M36: 18.5 | N36: 3 | O36: 8:50 | P36: 14 | R36: =$F$7*'Monday Est.'!N36*'Vehicle Infos'!$L$21 -> 42.545145 | AH36: Sunday | AI36: ='Sunday Est.'!G26 -> 25 | AJ36: ='Sunday Est.'!G41 -> 39 | AK36: ='Sunday Est.'!G56 -> 30 | AL36: ='Sunday Est.'!G71 -> 35 | AM36: ='Sunday Est.'!G86 -> 31
C37: Texaco Omnisport -Total Mfouda | D37: 14 | E37: 2 | F37: 8:27 | G37: 11 | I37: =$D$7*'Monday Est.'!E37*'Vehicle Infos'!$L$10 -> 109.69954 | L37: Total | N37: =SUM(N30:N36) -> 18.5 | P37: =SUM(P31:P36) -> 49.5 | Q37: =SUM(Q30) -> 815.8293 | R37: =$F$7*'Monday Est.'!N37*'Vehicle Infos'!$L$21 -> 262.36172
C38: Total Mfouda-Mobil Elig-Essono | D38: 14.5 | E38: 0.5 | F38: 8:3 | G38: 3 | I38: =$D$7*'Monday Est.'!E38*'Vehicle Infos'!$L$10 -> 27.424886
C39: Mobil Elig-Essono-Camair | D39: 15 | E39: 0.5 | F39: 8:32 | G39: 2 | I39: =$D$7*'Monday Est.'!E39*'Vehicle Infos'!$L$10 -> 27.424886
C40: Total | E40: 15 | G40: =SUM(G31:G39) -> 62 | H40: =H30 -> 1693.35 | I40: =$D$7*'Monday Est.'!E40*'Vehicle Infos'!$L$10 -> 822.74658
C42: 10:00-15:00 Scenario | L42: Monday 10:00-15:00 Scenario | U42: Monday 10:00-15:00 Scenario | AH42: Daily Tailpipe Emissions in kg CO2 (Tier 1)
C43: Soa-Yaounde: Road Network Stretches | D43: Cummulative distance (Km) | E43: Distance per stretch | F43: Clock Time | G43: Average time Taken (min) | H43: Tier 1 Emissions (kg CO2) (Daily) | I43: Tier 2 Emissions (kg CO2) (Daily) | L43: Mfou-Yaounde: Road Network Stretches | M43: Cummulative distance (Km) | N43: Distance per stretch | O43: Clock Time | P43: Average time Taken (min) | Q43: Tier 1 Emissions (kg CO2) (Daily) | R43: Tier 2 Emissions (kg CO2) (Daily) | U43: Mbankomo-Yaounde: Road Network Stretches | V43: Cummulative distance (Km) | W43: Distance per stretch | X43: Clock Time | Y43: Average time Taken (min) | Z43: Tier 1 Emissions (kg CO2) (Daily) | AA43: Tier 2 Emissions (kg CO2) (Daily) | AI43: 6:00 - 7:00 | AJ43: 7:00 - 10:00 | AK43: 10:00 - 15:00 | AL43: 15:00 - 19:00 | AM43: 19:00 - 22:00 | AN43: TOTAL
C44: Soa Centre | D44: 0 | E44: 0 | F44: 11:30 | H44: =D8*D3*'Vehicle Infos'!K10 -> 3211.8 | I44: =$D$8*'Monday Est.'!E44*'Vehicle Infos'!$L$10 -> 0 | L44: Marche Mfou | M44: 0 | N44: 0 | O44: 11:00 | Q44: =F8*F3*'Vehicle Infos'!K21 -> 951.80085 | R44: =$F$8*'Monday Est.'!N44*'Vehicle Infos'!$L$21 -> 0 | U44: Green oil | V44: 0 | W44: 0 | X44: 15:00 | Y44: 0 | Z44: =G8*G3*'Vehicle Infos'!K29 -> 483.12 | AA44: =$G$8*'Monday Est.'!W44*'Vehicle Infos'!$L$29 -> 0 | AG44: Soa | AH44: Tier 1 | AI44: =H16 -> 349.8 | AJ44: =H30 -> 1693.35 | AK44: =H44 -> 3211.8 | AL44: =H59 -> 1701.3 | AM44: =H73 -> 1510.5 | AN44: =SUM(AI44:AM44) -> 8466.75
...

Sheet Tuesday Est.
B2: Tuesday Tailpipe Emissions | D2: Soa | F2: Mfou | G2: Mbankomo | H2: Units
B3: Fuel consumed on total stretch | C3: Toyota | D3: 2.5 | F3: 3.3 | G3: 2.5 | H3: litres
C4: Mercedes | D4: 3 | H4: litres
B5: Number of buses | C5: Time frame | D5: Number of Vehicles
C6: 06:00 - 07:00 | D6: =40+13 -> 53 | F6: 17 | G6: 13
C7: 07:00 - 10:00 | D7: =140+69 -> 209 | F7: 76 | G7: 63
C8: 10:00 - 15:00 | D8: =220+168 -> 388 | F8: 86 | G8: 60
C9: 15:00 - 19:00 | D9: =126+86 -> 212 | F9: 85 | G9: 39
C10: 19:00 - 22:00 | D10: =119+66 -> 185 | F10: 34 | G10: 32
C11: Number of days in a year | D11: 365
C14: Tuesday 6:00-7:00 Scenario | H14: Daily Tail Pipe Emissions | L14: Tuesday 6:00-7:00 Scenario | Q14: Tail Pipe Emissions | U14: Tuesday 6:00-7:00 Scenario | AD14: Daily Tailpipe Emissions in kg CO2 (Tier 1)
C15: Soa-Yaounde: Road Network Stretches | D15: Cummulative distance (Km) | E15: Distance per stretch | F15: Clock Time | G15: Average time Taken (min) | H15: Tier 1 Emissions (kg CO2) (Daily) | I15: Tier 2 Emissions (kg CO2) (Daily) | L15: Mfou-Yaounde: Road Network Stretches | M15: Cummulative distance (Km) | N15: Distance per stretch | O15: Clock Time | P15: Average time Taken (min) | Q15: Tier 1 Emissions (kg CO2) (Daily) | R15: Tier 2 Emissions (kg CO2) (Daily) | U15: Mbankomo-Yaounde: Road Network Stretches | V15: Cummulative distance (Km) | W15: Distance per stretch | X15: Clock Time | Y15: Average time Taken (min) | Z15: Tier 1 Emissions (kg CO2) (Daily) | AA15: Tier 2 Emissions (kg CO2) (Daily) | AE15: 6:00 - 7:00 | AF15: 7:00 - 10:00 | AG15: 10:00 - 15:00 | AH15: 15:00 - 19:00 | AI15: 19:00 - 22:00 | AJ15: TOTAL
C16: Soa Centre | D16: 0 | E16: 0 | F16: 6:00 | G16: 0 | H16: =D6*D3*'Vehicle Infos'!K10 -> 421.35 | I16: =$D$6*E16*'Vehicle Infos'!$L$10 -> 0 | L16: Marche Mfou | M16: 0 | N16: 0 | O16: 6:10 | P16: 0 | Q16: =F6*F3*'Vehicle Infos'!K21 -> 177.80895 | R16: =$F$6*N16*'Vehicle Infos'!$L$21 -> 0 | U16: Green oil | V16: 0 | W16: 0 | X16: 6:15 | Y16: 0 | Z16: =G6*G3*'Vehicle Infos'!K29 -> 102.96 | AA16: =$G$6*W16*'Vehicle Infos'!$L$29 -> 0
C17: Soa Centre -Vallée vert | D17: 7.5 | E17: 7.5 | F17: 6:07 | G17: 7 | I17: =$D$6*E17*'Vehicle Infos'!$L$10 -> 102.36049 | L17: Marche Mfou - Gare Mfou | M17: 1 | N17: 1 | O17: 6:12 | P17: 2 | R17: =$F$6*N17*'Vehicle Infos'!$L$21 -> 3.0908866 | U17: Green oil - Entrée Ngoumou | V17: 3 | W17: 3 | X17: 6:21 | Y17: 5 | AA17: =$G$6*W17*'Vehicle Infos'!$L$29 -> 6.5165165
C18: Vallée vert -Petite marché | D18: 8 | E18: 0.5 | F18: 6:10 | G18: 3 | I18: =$D$6*E18*'Vehicle Infos'!$L$10 -> 6.8240327 | L18: Gare Mfou - Gustave Eiffel | M18: 2.5 | N18: 1.5 | O18: 6:17 | P18: 5 | R18: =$F$6*N18*'Vehicle Infos'!$L$21 -> 4.6363299 | U18: Entrée Ngoumou - Carrefour Nomayos | V18: 5.5 | W18: 2.5 | X18: 6:27 | Y18: 6 | AA18: =$G$6*W18*'Vehicle Infos'!$L$29 -> 5.4304304
C19: Petite marché-Eleveur | D19: 9 | E19: 1 | F19: 6:14 | G19: 4 | I19: =$D$6*E19*'Vehicle Infos'!$L$10 -> 13.648065 | L19: Gustave Eiffel - Entrée EP Meyo | M19: 9 | N19: 6.5 | O19: 6:26 | P19: 9 | R19: =$F$6*N19*'Vehicle Infos'!$L$21 -> 20.090763 | U19: Carrefour Nomayos - Entrée CIMENCAM | V19: 7.5 | W19: 2 | X19: 6:35 | Y19: 8 | AA19: =$G$6*W19*'Vehicle Infos'!$L$29 -> 4.3443443
C20: Eleveur-Total Ngoussou | D20: 10 | E20: 1 | F20: 6:18 | G20: 4 | I20: =$D$6*E20*'Vehicle Infos'!$L$10 -> 13.648065 | L20: Entrée EP Meyo - Carrefour Nkongoa | M20: 12 | N20: 3 | O20: 6:30 | P20: 4 | R20: =$F$6*N20*'Vehicle Infos'!$L$21 -> 9.2726597 | U20: Entrée CIMENCAM - Barrier (Tradex Ahala) | V20: 12 | W20: 4.5 | X20: 6:49 | Y20: 15 | AA20: =$G$6*W20*'Vehicle Infos'!$L$29 -> 9.7747748
C21: Total Ngoussou -Mobil Omnisport | D21: 11 | E21: 1 | F21: 6:25 | G21: 7 | I21: =$D$6*E21*'Vehicle Infos'!$L$10 -> 13.648065 | L21: Carrefour Nkongoa - Carrefour Monti | M21: 15.5 | N21: 3.5 | O21: 6:35 | P21: 5 | R21: =$F$6*N21*'Vehicle Infos'!$L$21 -> 10.818103 | U21: Total | W21: =SUM(W17:W20) -> 12 | Y21: =SUM(Y17:Y20) -> 34 | AA21: =$G$6*W21*'Vehicle Infos'!$L$29 -> 26.066066
C22: Mobil Omnisport -Texaco Omnisport | D22: 12 | E22: 1 | F22: 6:30 | G22: 5 | I22: =$D$6*E22*'Vehicle Infos'!$L$10 -> 13.648065 | L22: Carrefour Monti - Hawai Escallier | M22: 18.5 | N22: 3 | O22: 6:40 | P22: 5 | R22: =$F$6*N22*'Vehicle Infos'!$L$21 -> 9.2726597
C23: Texaco Omnisport -Total Mfouda | D23: 14 | E23: 2 | F23: 6:36 | G23: 6 | I23: =$D$6*E23*'Vehicle Infos'!$L$10 -> 27.296131 | L23: Total | N23: =SUM(N16:N22) -> 18.5 | P23: =SUM(P17:P22) -> 30 | Q23: =SUM(Q16) -> 177.80895 | R23: =$F$6*N23*'Vehicle Infos'!$L$21 -> 57.181402
C24: Total Mfouda-Mobil Elig-Essono | D24: 14.5 | E24: 0.5 | F24: 6:39 | G24: 3 | I24: =$D$6*E24*'Vehicle Infos'!$L$10 -> 6.8240327
C25: Mobil Elig-Essono-Camair | D25: 15 | E25: 0.5 | F25: 6:40 | G25: 1 | I25: =$D$6*E25*'Vehicle Infos'!$L$10 -> 6.8240327
C26: Total | E26: 15 | G26: =SUM(G17:G25) -> 40 | H26: =SUM(H16) -> 421.35 | I26: =$D$6*E26*'Vehicle Infos'!$L$10 -> 204.72098
C29: Tuesday 7:00-10:00 Scenario | L29: Tuesday 7:00-10:00 Scenario | U29: Tuesday 7:00-10:00 Scenario
C30: Soa-Yaounde: Road Network Stretches | D30: Cummulative distance (Km) | E30: Distance per stretch | F30: Clock Time | G30: Average time Taken (min) | H30: Tier 1 Emissions (kg CO2) (Daily) | I30: Tier 2 Emissions (kg CO2) (Daily) | L30: Mfou-Yaounde: Road Network Stretches | M30: Cummulative distance (Km) | N30: Distance per stretch | O30: Clock Time | P30: Average time Taken (min) | Q30: Tier 1 Emissions (kg CO2) (Daily) | R30: Tier 2 Emissions (kg CO2) (Daily) | U30: Mbankomo-Yaounde: Road Network Stretches | V30: Cummulative distance (Km) | W30: Distance per stretch | X30: Clock Time | Y30: Average time Taken (min) | Z30: Tier 1 Emissions (kg CO2) (Daily) | AA30: Tier 2 Emissions (kg CO2) (Daily)
C31: Soa Centre | D31: 0 | E31: 0 | F31: 7:30 | H31: =D7*D3*'Vehicle Infos'!K10 -> 1661.55 | I31: =$D$7*E31*'Vehicle Infos'!$L$10 -> 0 | L31: Marche Mfou | M31: 0 | N31: 0 | O31: 7:15 | Q31: =F7*F3*'Vehicle Infos'!K21 -> 794.9106 | R31: =$F$7*N31*'Vehicle Infos'!$L$21 -> 0 | U31: Green oil | V31: 0 | W31: 0 | X31: 7:15 | Y31: 0 | Z31: =G7*G3*'Vehicle Infos'!K29 -> 498.96 | AA31: =$G$7*W31*'Vehicle Infos'!$L$29 -> 0
C32: Soa Centre -Vallée vert | D32: 7.5 | E32: 7.5 | F32: 7:37 | G32: 7 | I32: =$D$7*E32*'Vehicle Infos'!$L$10 -> 403.64797 | L32: Marche Mfou - Gare Mfou | M32: 1 | N32: 1 | O32: 7:17 | P32: 2 | R32: =$F$7*N32*'Vehicle Infos'!$L$21 -> 13.818081 | U32: Green oil - Entrée Ngoumou | V32: 3 | W32: 3 | X32: 7:20 | Y32: 5 | AA32: =$G$7*W32*'Vehicle Infos'!$L$29 -> 31.580042
C33: Vallée vert -Petite marché | D33: 8 | E33: 0.5 | F33: 7:40 | G33: 3 | I33: =$D$7*E33*'Vehicle Infos'!$L$10 -> 26.909865 | L33: Gare Mfou - Gustave Eiffel | M33: 2.5 | N33: 1.5 | O33: 7:22 | P33: 5 | R33: =$F$7*N33*'Vehicle Infos'!$L$21 -> 20.727122 | U33: Entrée Ngoumou - Carrefour Nomayos | V33: 5.5 | W33: 2.5 | X33: 7:28 | Y33: 8 | AA33: =$G$7*W33*'Vehicle Infos'!$L$29 -> 26.316701
C34: Petite marché-Eleveur | D34: 9 | E34: 1 | F34: 7:48 | G34: 8 | I34: =$D$7*E34*'Vehicle Infos'!$L$10 -> 53.819729 | L34: Gustave Eiffel - Entrée EP Meyo | M34: 9 | N34: 6.5 | O34: 7:32 | P34: 10 | R34: =$F$7*N34*'Vehicle Infos'!$L$21 -> 89.817527 | U34: Carrefour Nomayos - Entrée CIMENCAM | V34: 7.5 | W34: 2 | X34: 7:40 | Y34: 12 | AA34: =$G$7*W34*'Vehicle Infos'!$L$29 -> 21.053361
C35: Eleveur-Total Ngoussou | D35: 10 | E35: 1 | F35: 7:55 | G35: 7 | I35: =$D$7*E35*'Vehicle Infos'!$L$10 -> 53.819729 | L35: Entrée EP Meyo - Carrefour Nkongoa | M35: 12 | N35: 3 | O35: 7:39 | P35: 7 | R35: =$F$7*N35*'Vehicle Infos'!$L$21 -> 41.454243 | U35: Entrée CIMENCAM - Barrier (Tradex Ahala) | V35: 12 | W35: 4.5 | X35: 8:05 | Y35: 25 | AA35: =$G$7*W35*'Vehicle Infos'!$L$29 -> 47.370062
C36: Total Ngoussou -Mobil Omnisport | D36: 11 | E36: 1 | F36: 8:09 | G36: 14 | I36: =$D$7*E36*'Vehicle Infos'!$L$10 -> 53.819729 | L36: Carrefour Nkongoa - Carrefour Monti | M36: 15.5 | N36: 3.5 | O36: 7:51 | P36: 12 | R36: =$F$7*N36*'Vehicle Infos'!$L$21 -> 48.363284 | U36: Total | W36: =SUM(W32:W35) -> 12 | Y36: =SUM(Y31:Y35) -> 50 | AA36: =$G$7*W36*'Vehicle Infos'!$L$29 -> 126.32017
C37: Mobil Omnisport -Texaco Omnisport | D37: 12 | E37: 1 | F37: 8:16 | G37: 7 | I37: =$D$7*E37*'Vehicle Infos'!$L$10 -> 53.819729 | L37: Carrefour Monti - Hawai Escallier | M37: 18.5 | N37: 3 | O37: 8:06 | P37: 15 | R37: =$F$7*N37*'Vehicle Infos'!$L$21 -> 41.454243
C38: Texaco Omnisport -Total Mfouda | D38: 14 | E38: 2 | F38: 8:25 | G38: 9 | I38: =$D$7*E38*'Vehicle Infos'!$L$10 -> 107.63946 | L38: Total | N38: =SUM(N31:N37) -> 18.5 | P38: =SUM(P32:P37) -> 51 | Q38: =SUM(Q31) -> 794.9106 | R38: =$F$7*N38*'Vehicle Infos'!$L$21 -> 255.6345
C39: Total Mfouda-Mobil Elig-Essono | D39: 14.5 | E39: 0.5 | F39: 8:28 | G39: 3 | I39: =$D$7*E39*'Vehicle Infos'!$L$10 -> 26.909865
C40: Mobil Elig-Essono-Camair | D40: 15 | E40: 0.5 | F40: 8:30 | G40: 2 | I40: =$D$7*E40*'Vehicle Infos'!$L$10 -> 26.909865
C41: Total | E41: 15 | G41: =SUM(G32:G40) -> 60 | H41: =SUM(H31) -> 1661.55 | I41: =$D$7*E41*'Vehicle Infos'!$L$10 -> 807.29594
C44: Tuesday 10:00-15:00 Scenario | L44: Tuesday 10:00-15:00 Scenario | U44: Tuesday 10:00-15:00 Scenario
C45: Soa-Yaounde: Road Network Stretches | D45: Cummulative distance (Km) | E45: Distance per stretch | F45: Clock Time | G45: Average time Taken (min) | H45: Tier 1 Emissions (kg CO2) (Daily) | I45: Tier 2 Emissions (kg CO2) (Daily) | L45: Mfou-Yaounde: Road Network Stretches | M45: Cummulative distance (Km) | N45: Distance per stretch | O45: Clock Time | P45: Average time Taken (min) | Q45: Tier 1 Emissions (kg CO2) (Daily) | R45: Tier 2 Emissions (kg CO2) (Daily) | U45: Mbankomo-Yaounde: Road Network Stretches | V45: Cummulative distance (Km) | W45: Distance per stretch | X45: Clock Time | Y45: Average time Taken (min) | Z45: Tier 1 Emissions (kg CO2) (Daily) | AA45: Tier 2 Emissions (kg CO2) (Daily)
C46: Soa Centre | D46: 0 | E46: 0 | F46: 11:30 | H46: =D8*D3*'Vehicle Infos'!K10 -> 3084.6 | I46: =$D$8*E46*'Vehicle Infos'!$L$10 -> 0 | L46: Marche Mfou | M46: 0 | N46: 0 | O46: 11:00 | Q46: =F8*F3*'Vehicle Infos'!K21 -> 899.5041 | R46: =$F$8*N46*'Vehicle Infos'!$L$21 -> 0 | U46: Green oil | V46: 0 | W46: 0 | X46: 10:00 | Y46: 0 | Z46: =G8*G3*'Vehicle Infos'!K29 -> 475.2 | AA46: =$G$8*W46*'Vehicle Infos'!$L$29 -> 0
C47: Soa Centre -Vallée vert | D47: 7.5 | E47: 7.5 | F47: 11:37 | G47: 7 | I47: =$D$8*E47*'Vehicle Infos'!$L$10 -> 749.35604 | L47: Marche Mfou - Gare Mfou | M47: 1 | N47: 1 | O47: 11:02 | P47: 2 | R47: =$F$8*N47*'Vehicle Infos'!$L$21 -> 15.63625 | U47: Green oil - Entrée Ngoumou | V47: 3 | W47: 3 | X47: 10:05 | Y47: 5 | AA47: =$G$8*W47*'Vehicle Infos'!$L$29 -> 30.07623
...

Sheet Wednesday Est.
B2: Wednesday Tailpipe Emissions | D2: Soa | F2: Mfou | G2: Mbankomo
B3: Fuel consumed on total stretch | C3: Toyota | D3: 2.5 | F3: 3.3 | G3: 2.5 | H3: litres
C4: Mercedes | D4: 3 | H4: litres
B5: Number of buses | C5: Time frame | D5: Number of Vehicles
C6: 06:00 - 07:00 | D6: =36+14 -> 50 | F6: 17 | G6: 11
C7: 07:00 - 10:00 | D7: =142+69 -> 211 | F7: 77 | G7: 64
C8: 10:00 - 15:00 | D8: =202+142 -> 344 | F8: 87 | G8: 56
C9: 15:00 - 19:00 | D9: =111+82 -> 193 | F9: 84 | G9: 33
C10: 19:00 - 22:00 | D10: =113+66 -> 179 | F10: 31 | G10: 31
C11: Number of days in a year | D11: 365
C14: Wednesday 6:00-7:00 Scenario | H14: Daily Tail Pipe Emissions | L14: Wednesday 6:00-7:00 Scenario | U14: Wednesday 6:00-7:00 Scenario | AD14: Annual Tailpipe Emissions in kg CO2 (Tier 1)
C15: Soa-Yaounde: Road Network Stretches | D15: Cummulative distance (Km) | E15: Distance per stretch | F15: Clock Time | G15: Average time Taken (min) | H15: Tier 1 Emissions (kg CO2) (Daily) | I15: Tier 2 Emissions (kg CO2) (Daily) | L15: Mfou-Yaounde: Road Network Stretches | M15: Cummulative distance (Km) | N15: Distance per stretch | O15: Clock Time | P15: Average time Taken (min) | Q15: Tier 1 Emissions (kg CO2) (Daily) | R15: Tier 2 Emissions (kg CO2) (Daily) | U15: Mbankomo-Yaounde: Road Network Stretches | V15: Cummulative distance (Km) | W15: Distance per stretch | X15: Clock Time | Y15: Average time Taken (min) | Z15: Tier 1 Emissions (kg CO2) (Daily) | AA15: Tier 2 Emissions (kg CO2) (Daily) | AF15: 6:00 - 7:00 | AG15: 7:00 - 10:00 | AH15: 10:00 - 15:00 | AI15: 15:00 - 19:00 | AJ15: 19:00 - 22:00 | AK15: TOTAL
C16: Soa Centre | D16: 0 | E16: 0 | F16: 6:00 | G16: 0 | H16: =D6*D3*'Vehicle Infos'!K10 -> 397.5 | I16: =$D$6*E16*'Vehicle Infos'!$L$10 -> 0 | L16: Marche Mfou | M16: 0 | N16: 0 | O16: 6:00 | P16: 0 | Q16: =F6*F3*'Vehicle Infos'!K21 -> 177.80895 | R16: =$F$6*N16*'Vehicle Infos'!$L$21 -> 0 | U16: Green oil | V16: 0 | W16: 0 | X16: 6:00 | Y16: 0 | Z16: =G6*G3*'Vehicle Infos'!K29 -> 87.12 | AA16: =$G$6*W16*'Vehicle Infos'!$L$29 -> 0 | AD16: Wednesday | AE16: Soa | AF16: =SUM(H16:H25)*D11 -> 145087.5 | AG16: =SUM(H31:H40)*D11 -> 612269.25 | AH16: =SUM(H46:H55)*D11 -> 998202 | AI16: =SUM(H61:H70)*D11 -> 560037.75 | AJ16: =SUM(H76:H85)*D11 -> 519413.25 | AK16: =SUM(AF16:AJ16) -> 2835009.8
C17: Soa Centre -Vallée vert | D17: 7.5 | E17: 7.5 | F17: 6:07 | G17: 7 | I17: =$D$6*E17*'Vehicle Infos'!$L$10 -> 96.5665 | L17: Marche Mfou - Gare Mfou | M17: 1 | N17: 1 | O17: 6:02 | P17: 2 | R17: =$F$6*N17*'Vehicle Infos'!$L$21 -> 3.0908866 | U17: Green oil - Entrée Ngoumou | V17: 3 | W17: 3 | X17: 6:05 | Y17: 5 | AA17: =$G$6*W17*'Vehicle Infos'!$L$29 -> 5.5139755 | AE17: Mfou
C18: Vallée vert -Petite marché | D18: 8 | E18: 0.5 | F18: 6:10 | G18: 3 | I18: =$D$6*E18*'Vehicle Infos'!$L$10 -> 6.4377667 | L18: Gare Mfou - Gustave Eiffel | M18: 2.5 | N18: 1.5 | O18: 6:07 | P18: 5 | R18: =$F$6*N18*'Vehicle Infos'!$L$21 -> 4.6363299 | U18: Entrée Ngoumou - Carrefour Nomayos | V18: 5.5 | W18: 2.5 | X18: 6:11 | Y18: 6 | AA18: =$G$6*W18*'Vehicle Infos'!$L$29 -> 4.5949796 | AE18: Mbankomo
C19: Petite marché-Eleveur | D19: 9 | E19: 1 | F19: 6:14 | G19: 4 | I19: =$D$6*E19*'Vehicle Infos'!$L$10 -> 12.875533 | L19: Gustave Eiffel - Entrée EP Meyo | M19: 9 | N19: 6.5 | O19: 6:16 | P19: 9 | R19: =$F$6*N19*'Vehicle Infos'!$L$21 -> 20.090763 | U19: Carrefour Nomayos - Entrée CIMENCAM | V19: 7.5 | W19: 2 | X19: 6:19 | Y19: 8 | AA19: =$G$6*W19*'Vehicle Infos'!$L$29 -> 3.6759837
C20: Eleveur-Total Ngoussou | D20: 10 | E20: 1 | F20: 6:18 | G20: 4 | I20: =$D$6*E20*'Vehicle Infos'!$L$10 -> 12.875533 | L20: Entrée EP Meyo - Carrefour Nkongoa | M20: 12 | N20: 3 | O20: 6:20 | P20: 4 | R20: =$F$6*N20*'Vehicle Infos'!$L$21 -> 9.2726597 | U20: Entrée CIMENCAM - Barrier (Tradex Ahala) | V20: 12 | W20: 4.5 | X20: 6:34 | Y20: 15 | AA20: =$G$6*W20*'Vehicle Infos'!$L$29 -> 8.2709633
C21: Total Ngoussou -Mobil Omnisport | D21: 11 | E21: 1 | F21: 6:24 | G21: 6 | I21: =$D$6*E21*'Vehicle Infos'!$L$10 -> 12.875533 | L21: Carrefour Nkongoa - Carrefour Monti | M21: 15.5 | N21: 3.5 | O21: 6:25 | P21: 5 | R21: =$F$6*N21*'Vehicle Infos'!$L$21 -> 10.818103 | U21: Total | W21: =SUM(W16:W20) -> 12 | Y21: =SUM(Y16:Y20) -> 34 | AA21: =$G$6*W21*'Vehicle Infos'!$L$29 -> 22.055902
C22: Mobil Omnisport -Texaco Omnisport | D22: 12 | E22: 1 | F22: 6:28 | G22: 4 | I22: =$D$6*E22*'Vehicle Infos'!$L$10 -> 12.875533 | L22: Carrefour Monti - Hawai Escallier | M22: 18.5 | N22: 3 | O22: 6:31 | P22: 6 | R22: =$F$6*N22*'Vehicle Infos'!$L$21 -> 9.2726597
C23: Texaco Omnisport -Total Mfouda | D23: 14 | E23: 2 | F23: 6:33 | G23: 5 | I23: =$D$6*E23*'Vehicle Infos'!$L$10 -> 25.751067 | L23: Total | N23: =SUM(N16:N22) -> 18.5 | P23: =SUM(P17:P22) -> 31 | R23: =$F$6*N23*'Vehicle Infos'!$L$21 -> 57.181402
C24: Total Mfouda-Mobil Elig-Essono | D24: 14.5 | E24: 0.5 | F24: 6:36 | G24: 3 | I24: =$D$6*E24*'Vehicle Infos'!$L$10 -> 6.4377667
C25: Mobil Elig-Essono-Camair | D25: 15 | E25: 0.5 | F25: 6:37 | G25: 1 | I25: =$D$6*E25*'Vehicle Infos'!$L$10 -> 6.4377667
C26: Total | E26: 15 | G26: =SUM(G17:G25) -> 37 | I26: =$D$6*E26*'Vehicle Infos'!$L$10 -> 193.133
C29: Wednesday 7:00-10:00 Scenario | L29: Wednesday 7:00-10:00 Scenario | U29: Wednesday 7:00-10:00 Scenario
C30: Soa-Yaounde: Road Network Stretches | D30: Cummulative distance (Km) | E30: Distance per stretch | F30: Clock Time | G30: Average time Taken (min) | H30: Tier 1 Emissions (kg CO2) (Daily) | I30: Tier 2 Emissions (kg CO2) (Daily) | L30: Mfou-Yaounde: Road Network Stretches | M30: Cummulative distance (Km) | N30: Distance per stretch | O30: Clock Time | P30: Average time Taken (min) | Q30: Tier 1 Emissions (kg CO2) (Daily) | R30: Tier 2 Emissions (kg CO2) (Daily) | U30: Mbankomo-Yaounde: Road Network Stretches | V30: Cummulative distance (Km) | W30: Distance per stretch | X30: Clock Time | Y30: Average time Taken (min) | Z30: Tier 1 Emissions (kg CO2) (Daily) | AA30: Tier 2 Emissions (kg CO2) (Daily)
C31: Soa Centre | D31: 0 | E31: 0 | F31: 7:30 | H31: =D7*D3*'Vehicle Infos'!K10 -> 1677.45 | I31: =$D$7*E31*'Vehicle Infos'!$L$10 -> 0 | L31: Marche Mfou | M31: 0 | N31: 0 | O31: 7:00 | P31: 0 | Q31: =F7*F3*'Vehicle Infos'!K21 -> 805.36995 | R31: =$F$7*N31*'Vehicle Infos'!$L$21 -> 0 | U31: Green oil | V31: 0 | W31: 0 | X31: 7:00 | Y31: 0 | Z31: =G7*G3*'Vehicle Infos'!K29 -> 506.88 | AA31: =$G$7*W31*'Vehicle Infos'!$L$29 -> 0
C32: Soa Centre -Vallée vert | D32: 7.5 | E32: 7.5 | F32: 7:37 | G32: 7 | I32: =$D$7*E32*'Vehicle Infos'!$L$10 -> 407.51063 | L32: Marche Mfou - Gare Mfou | M32: 1 | N32: 1 | O32: 7:02 | P32: 2 | R32: =$F$7*N32*'Vehicle Infos'!$L$21 -> 13.999898 | U32: Green oil - Entrée Ngoumou | V32: 3 | W32: 3 | X32: 7:05 | Y32: 5 | AA32: =$G$7*W32*'Vehicle Infos'!$L$29 -> 32.081312
C33: Vallée vert -Petite marché | D33: 8 | E33: 0.5 | F33: 7:40 | G33: 3 | I33: =$D$7*E33*'Vehicle Infos'!$L$10 -> 27.167375 | L33: Gare Mfou - Gustave Eiffel | M33: 2.5 | N33: 1.5 | O33: 7:08 | P33: 6 | R33: =$F$7*N33*'Vehicle Infos'!$L$21 -> 20.999847 | U33: Entrée Ngoumou - Carrefour Nomayos | V33: 5.5 | W33: 2.5 | X33: 7:13 | Y33: 8 | AA33: =$G$7*W33*'Vehicle Infos'!$L$29 -> 26.734427
C34: Petite marché-Eleveur | D34: 9 | E34: 1 | F34: 7:48 | G34: 8 | I34: =$D$7*E34*'Vehicle Infos'!$L$10 -> 54.334751 | L34: Gustave Eiffel - Entrée EP Meyo | M34: 9 | N34: 6.5 | O34: 7:17 | P34: 9 | R34: =$F$7*N34*'Vehicle Infos'!$L$21 -> 90.999337 | U34: Carrefour Nomayos - Entrée CIMENCAM | V34: 7.5 | W34: 2 | X34: 7:24 | Y34: 11 | AA34: =$G$7*W34*'Vehicle Infos'!$L$29 -> 21.387541
C35: Eleveur-Total Ngoussou | D35: 10 | E35: 1 | F35: 7:55 | G35: 7 | I35: =$D$7*E35*'Vehicle Infos'!$L$10 -> 54.334751 | L35: Entrée EP Meyo - Carrefour Nkongoa | M35: 12 | N35: 3 | O35: 7:23 | P35: 6 | R35: =$F$7*N35*'Vehicle Infos'!$L$21 -> 41.999694 | U35: Entrée CIMENCAM - Barrier (Tradex Ahala) | V35: 12 | W35: 4.5 | X35: 7:50 | Y35: 26 | AA35: =$G$7*W35*'Vehicle Infos'!$L$29 -> 48.121968
C36: Total Ngoussou -Mobil Omnisport | D36: 11 | E36: 1 | F36: 8:08 | G36: 13 | I36: =$D$7*E36*'Vehicle Infos'!$L$10 -> 54.334751 | L36: Carrefour Nkongoa - Carrefour Monti | M36: 15.5 | N36: 3.5 | O36: 7:31 | P36: 8 | R36: =$F$7*N36*'Vehicle Infos'!$L$21 -> 48.999643 | U36: Total | W36: =SUM(W31:W35) -> 12 | Y36: =SUM(Y31:Y35) -> 50 | AA36: =$G$7*W36*'Vehicle Infos'!$L$29 -> 128.32525
C37: Mobil Omnisport -Texaco Omnisport | D37: 12 | E37: 1 | F37: 8:14 | G37: 6 | I37: =$D$7*E37*'Vehicle Infos'!$L$10 -> 54.334751 | L37: Carrefour Monti - Hawai Escallier | M37: 18.5 | N37: 3 | O37: 7:40 | P37: 9 | R37: =$F$7*N37*'Vehicle Infos'!$L$21 -> 41.999694
C38: Texaco Omnisport -Total Mfouda | D38: 14 | E38: 2 | F38: 8:25 | G38: 11 | I38: =$D$7*E38*'Vehicle Infos'!$L$10 -> 108.6695 | L38: Total | N38: =SUM(N31:N37) -> 18.5 | P38: =SUM(P32:P37) -> 40 | R38: =$F$7*N38*'Vehicle Infos'!$L$21 -> 258.99811
C39: Total Mfouda-Mobil Elig-Essono | D39: 14.5 | E39: 0.5 | F39: 8:28 | G39: 3 | I39: =$D$7*E39*'Vehicle Infos'!$L$10 -> 27.167375
C40: Mobil Elig-Essono-Camair | D40: 15 | E40: 0.5 | F40: 8:30 | G40: 2 | I40: =$D$7*E40*'Vehicle Infos'!$L$10 -> 27.167375
C41: Total | E41: 15 | G41: =SUM(G32:G40) -> 60 | I41: =$D$7*E41*'Vehicle Infos'!$L$10 -> 815.02126
C44: Wednesday 10:00-15:00 Scenario | L44: Wednesday 10:00-15:00 Scenario | U44: Wednesday 10:00-15:00 Scenario
C45: Soa-Yaounde: Road Network Stretches | D45: Cummulative distance (Km) | E45: Distance per stretch | F45: Clock Time | G45: Average time Taken (min) | H45: Tier 1 Emissions (kg CO2) (Daily) | I45: Tier 2 Emissions (kg CO2) (Daily) | L45: Mfou-Yaounde: Road Network Stretches | M45: Cummulative distance (Km) | N45: Distance per stretch | O45: Clock Time | P45: Average time Taken (min) | Q45: Tier 1 Emissions (kg CO2) (Daily) | R45: Tier 2 Emissions (kg CO2) (Daily) | U45: Mbankomo-Yaounde: Road Network Stretches | V45: Cummulative distance (Km) | W45: Distance per stretch | X45: Clock Time | Y45: Average time Taken (min) | Z45: Tier 1 Emissions (kg CO2) (Daily) | AA45: Tier 2 Emissions (kg CO2) (Daily)
C46: Soa Centre | D46: 0 | E46: 0 | F46: 11:30 | H46: =D8*D3*'Vehicle Infos'!K10 -> 2734.8 | I46: =$D$8*E46*'Vehicle Infos'!$L$10 -> 0 | L46: Marche Mfou | M46: 0 | N46: 0 | O46: 10:00 | Q46: =F8*F3*'Vehicle Infos'!K21 -> 909.96345 | R46: =$F$8*N46*'Vehicle Infos'!$L$21 -> 0 | U46: Green oil | V46: 0 | W46: 0 | X46: 10:00 | Y46: 0 | Z46: =G8*G3*'Vehicle Infos'!K29 -> 443.52 | AA46: =$G$8*W46*'Vehicle Infos'!$L$29 -> 0
C47: Soa Centre -Vallée vert | D47: 7.5 | E47: 7.5 | F47: 11:37 | G47: 7 | I47: =$D$8*E47*'Vehicle Infos'!$L$10 -> 664.37752 | L47: Marche Mfou - Gare Mfou | M47: 1 | N47: 1 | O47: 10:02 | P47: 2 | R47: =$F$8*N47*'Vehicle Infos'!$L$21 -> 15.818067 | U47: Green oil - Entrée Ngoumou | V47: 3 | W47: 3 | X47: 10:05 | Y47: 5 | AA47: =$G$8*W47*'Vehicle Infos'!$L$29 -> 28.071148
...

Sheet Thursday Est.
B2: Thursday Tailpipe Emissions | D2: SOA | F2: MFOU | G2: Mbankomo
B3: Fuel consumed on total stretch | C3: Toyota | D3: 2.5 | F3: 3.3 | G3: 2.5 | H3: litres
C4: Mercedes | D4: 3 | H4: litres
B5: Number of buses | C5: Time frame | D5: Number of Vehicles
C6: 06:00 - 07:00 | D6: =36+14 -> 50 | F6: 14 | G6: 11
C7: 07:00 - 10:00 | D7: =142+69 -> 211 | F7: 74 | G7: 61
C8: 10:00 - 15:00 | D8: =202+142 -> 344 | F8: 87 | G8: 52
C9: 15:00 - 19:00 | D9: =111+82 -> 193 | F9: 84 | G9: 33
C10: 19:00 - 22:00 | D10: =113+66 -> 179 | F10: 29 | G10: 29
C11: Number of days in a year | D11: 365
C14: Thursday 6:00-7:00 Scenario | H14: Daily Tail Pipe Emissions | M14: Thursday 6:00-7:00 Scenario | V14: Thursday 6:00-7:00 Scenario | AH14: Annual Tailpipe Emissions in kg CO2 (Tier 1)
C15: Soa-Yaounde: Road Network Stretches | D15: Cummulative distance (Km) | E15: Distance per stretch | F15: Clock Time | G15: Average time Taken (min) | H15: Tier 1 Emissions (kg CO2) (Daily) | I15: Tier 2 Emissions (kg CO2) (Daily) | M15: Mfou-Yaounde: Road Network Stretches | N15: Cummulative distance (Km) | O15: Distance per stretch | P15: Clock Time | Q15: Average time Taken (min) | R15: Tier 1 Emissions (kg CO2) (Daily) | S15: Tier 2 Emissions (kg CO2) (Daily) | V15: Mbankomo-Yaounde: Road Network Stretches | W15: Cummulative distance (Km) | X15: Distance per stretch | Y15: Clock Time | Z15: Average time Taken (min) | AA15: Tier 1 Emissions (kg CO2) (Daily) | AB15: Tier 2 Emissions (kg CO2) (Daily) | AI15: 6:00 - 7:00 | AJ15: 7:00 - 10:00 | AK15: 10:00 - 15:00 | AL15: 15:00 - 19:00 | AM15: 19:00 - 22:00 | AN15: TOTAL
C16: Soa Centre | D16: 0 | E16: 0 | F16: 6.00 | H16: =D6*D3*'Vehicle Infos'!K10 -> 397.5 | I16: =$D$6*E16*'Vehicle Infos'!$L$10 -> 0 | M16: Marche Mfou | N16: 0 | O16: 0 | P16: 6:00 | Q16: 0 | R16: =F6*F3*'Vehicle Infos'!K21 -> 146.4309 | S16: =$F$6*O16*'Vehicle Infos'!$L$21 -> 0 | V16: Green oil | W16: 0 | X16: 0 | Y16: 6:00 | Z16: 0 | AA16: =G6*G3*'Vehicle Infos'!K29 -> 87.12 | AB16: =$G$6*X16*'Vehicle Infos'!$L$29 -> 0 | AH16: Thursday | AI16: =SUM(H16:H25)*D11 -> 145087.5 | AJ16: =SUM(H31:H40)*D11 -> 612269.25 | AK16: =SUM(H46:H55)*D11 -> 998202 | AL16: =SUM(H61:H70)*D11 -> 560037.75 | AM16: =SUM(H76:H85)*D11 -> 519413.25 | AN16: =SUM(AI16:AM16) -> 2835009.8
C17: Soa Centre -Vallée vert | D17: 7.5 | E17: 7.5 | F17: 6:07 | G17: 7 | I17: =$D$6*E17*'Vehicle Infos'!$L$10 -> 96.5665 | M17: Marche Mfou - Gare Mfou | N17: 1 | O17: 1 | P17: 6:02 | Q17: 2 | S17: =$F$6*O17*'Vehicle Infos'!$L$21 -> 2.545436 | V17: Green oil - Entrée Ngoumou | W17: 3 | X17: 3 | Y17: 6:05 | Z17: 5 | AB17: =$G$6*X17*'Vehicle Infos'!$L$29 -> 5.5139755
C18: Vallée vert -Petite marché | D18: 8 | E18: 0.5 | F18: 6:09 | G18: 2 | I18: =$D$6*E18*'Vehicle Infos'!$L$10 -> 6.4377667 | M18: Gare Mfou - Gustave Eiffel | N18: 2.5 | O18: 1.5 | P18: 6:07 | Q18: 5 | S18: =$F$6*O18*'Vehicle Infos'!$L$21 -> 3.818154 | V18: Entrée Ngoumou - Carrefour Nomayos | W18: 5.5 | X18: 2.5 | Y18: 6:11 | Z18: 6 | AB18: =$G$6*X18*'Vehicle Infos'!$L$29 -> 4.5949796
C19: Petite marché-Eleveur | D19: 9 | E19: 1 | F19: 6:14 | G19: 5 | I19: =$D$6*E19*'Vehicle Infos'!$L$10 -> 12.875533 | M19: Gustave Eiffel - Entrée EP Meyo | N19: 9 | O19: 6.5 | P19: 6:16 | Q19: 9 | S19: =$F$6*O19*'Vehicle Infos'!$L$21 -> 16.545334 | V19: Carrefour Nomayos - Entrée CIMENCAM | W19: 7.5 | X19: 2 | Y19: 6:19 | Z19: 8 | AB19: =$G$6*X19*'Vehicle Infos'!$L$29 -> 3.6759837
C20: Eleveur-Total Ngoussou | D20: 10 | E20: 1 | F20: 6:17 | G20: 3 | I20: =$D$6*E20*'Vehicle Infos'!$L$10 -> 12.875533 | M20: Entrée EP Meyo - Carrefour Nkongoa | N20: 12 | O20: 3 | P20: 6:20 | Q20: 4 | S20: =$F$6*O20*'Vehicle Infos'!$L$21 -> 7.636308 | V20: Entrée CIMENCAM - Barrier (Tradex Ahala) | W20: 12 | X20: 4.5 | Y20: 6:33 | Z20: 14 | AB20: =$G$6*X20*'Vehicle Infos'!$L$29 -> 8.2709633
C21: Total Ngoussou -Mobil Omnisport | D21: 11 | E21: 1 | F21: 7:26 | G21: 9 | I21: =$D$6*E21*'Vehicle Infos'!$L$10 -> 12.875533 | M21: Carrefour Nkongoa - Carrefour Monti | N21: 15.5 | O21: 3.5 | P21: 6:25 | Q21: 5 | S21: =$F$6*O21*'Vehicle Infos'!$L$21 -> 8.909026 | V21: Total | X21: =SUM(X17:X20) -> 12 | Z21: =SUM(Z16:Z20) -> 33 | AB21: =$G$6*X21*'Vehicle Infos'!$L$29 -> 22.055902
C22: Mobil Omnisport -Texaco Omnisport | D22: 12 | E22: 1 | F22: 7:28 | G22: 2 | I22: =$D$6*E22*'Vehicle Infos'!$L$10 -> 12.875533 | M22: Carrefour Monti - Hawai Escallier | N22: 18.5 | O22: 3 | P22: 6:30 | Q22: 5 | S22: =$F$6*O22*'Vehicle Infos'!$L$21 -> 7.636308
C23: Texaco Omnisport -Total Mfouda | D23: 14 | E23: 2 | F23: 7:34 | G23: 6 | I23: =$D$6*E23*'Vehicle Infos'!$L$10 -> 25.751067 | M23: Total | O23: =SUM(O16:O22) -> 18.5 | Q23: =SUM(Q17:Q22) -> 30 | S23: =$F$6*O23*'Vehicle Infos'!$L$21 -> 47.090566
C24: Total Mfouda-Mobil Elig-Essono | D24: 14.5 | E24: 0.5 | F24: 7:35 | G24: 1 | I24: =$D$6*E24*'Vehicle Infos'!$L$10 -> 6.4377667
C25: Mobil Elig-Essono-Camair | D25: 15 | E25: 0.5 | F25: 7:36 | G25: 1 | I25: =$D$6*E25*'Vehicle Infos'!$L$10 -> 6.4377667
C26: Total | E26: 15 | G26: =SUM(G17:G25) -> 36 | I26: =$D$6*E26*'Vehicle Infos'!$L$10 -> 193.133
C29: Thursday 7:00-10:00 Scenario | M29: Thursday 7:00-10:00 Scenario | V29: Thursday 7:00-10:00 Scenario
C30: Soa-Yaounde: Road Network Stretches | D30: Cummulative distance (Km) | E30: Distance per stretch | F30: Clock Time | G30: Average time Taken (min) | H30: Tier 1 Emissions (kg CO2) (Daily) | I30: Tier 2 Emissions (kg CO2) (Daily) | M30: Mfou-Yaounde: Road Network Stretches | N30: Cummulative distance (Km) | O30: Distance per stretch | P30: Clock Time | Q30: Average time Taken (min) | R30: Tier 1 Emissions (kg CO2) (Daily) | S30: Tier 2 Emissions (kg CO2) (Daily) | V30: Mbankomo-Yaounde: Road Network Stretches | W30: Cummulative distance (Km) | X30: Distance per stretch | Y30: Clock Time | Z30: Average time Taken (min) | AA30: Tier 1 Emissions (kg CO2) (Daily) | AB30: Tier 2 Emissions (kg CO2) (Daily)
C31: Soa Centre | D31: 0 | E31: 0 | F31: 7:30 | H31: =D7*D3*'Vehicle Infos'!K10 -> 1677.45 | I31: =$D$7*E31*'Vehicle Infos'!$L$10 -> 0 | M31: Marche Mfou | N31: 0 | O31: 0 | P31: 7:00 | Q31: 0 | R31: =F7*F3*'Vehicle Infos'!K21 -> 773.9919 | S31: =$F$7*O31*'Vehicle Infos'!$L$21 -> 0 | V31: Green oil | W31: 0 | X31: 0 | Y31: 7:00 | Z31: 0 | AA31: =G7*G3*'Vehicle Infos'!K29 -> 483.12 | AB31: =$G$7*X31*'Vehicle Infos'!$L$29 -> 0
C32: Soa Centre -Vallée vert | D32: 7.5 | E32: 7.5 | F32: 7:37 | G32: 7 | I32: =$D$7*E32*'Vehicle Infos'!$L$10 -> 407.51063 | M32: Marche Mfou - Gare Mfou | N32: 1 | O32: 1 | P32: 7:02 | Q32: 2 | S32: =$F$7*O32*'Vehicle Infos'!$L$21 -> 13.454447 | V32: Green oil - Entrée Ngoumou | W32: 3 | X32: 3 | Y32: 7:05 | Z32: 5 | AB32: =$G$7*X32*'Vehicle Infos'!$L$29 -> 30.577501
C33: Vallée vert -Petite marché | D33: 8 | E33: 0.5 | F33: 7:43 | G33: 6 | I33: =$D$7*E33*'Vehicle Infos'!$L$10 -> 27.167375 | M33: Gare Mfou - Gustave Eiffel | N33: 2.5 | O33: 1.5 | P33: 7:07 | Q33: 5 | S33: =$F$7*O33*'Vehicle Infos'!$L$21 -> 20.181671 | V33: Entrée Ngoumou - Carrefour Nomayos | W33: 5.5 | X33: 2.5 | Y33: 7:13 | Z33: 8 | AB33: =$G$7*X33*'Vehicle Infos'!$L$29 -> 25.48125
C34: Petite marché-Eleveur | D34: 9 | E34: 1 | F34: 7:49 | G34: 6 | I34: =$D$7*E34*'Vehicle Infos'!$L$10 -> 54.334751 | M34: Gustave Eiffel - Entrée EP Meyo | N34: 9 | O34: 6.5 | P34: 7:17 | Q34: 10 | S34: =$F$7*O34*'Vehicle Infos'!$L$21 -> 87.453908 | V34: Carrefour Nomayos - Entrée CIMENCAM | W34: 7.5 | X34: 2 | Y34: 7:24 | Z34: 11 | AB34: =$G$7*X34*'Vehicle Infos'!$L$29 -> 20.385
C35: Eleveur-Total Ngoussou | D35: 10 | E35: 1 | F35: 8:05 | G35: 16 | I35: =$D$7*E35*'Vehicle Infos'!$L$10 -> 54.334751 | M35: Entrée EP Meyo - Carrefour Nkongoa | N35: 12 | O35: 3 | P35: 7:23 | Q35: 6 | S35: =$F$7*O35*'Vehicle Infos'!$L$21 -> 40.363342 | V35: Entrée CIMENCAM - Barrier (Tradex Ahala) | W35: 12 | X35: 4.5 | Y35: 7:49 | Z35: 25 | AB35: =$G$7*X35*'Vehicle Infos'!$L$29 -> 45.866251
C36: Total Ngoussou -Mobil Omnisport | D36: 11 | E36: 1 | F36: 8:08 | G36: 3 | I36: =$D$7*E36*'Vehicle Infos'!$L$10 -> 54.334751 | M36: Carrefour Nkongoa - Carrefour Monti | N36: 15.5 | O36: 3.5 | P36: 7:34 | Q36: 11 | S36: =$F$7*O36*'Vehicle Infos'!$L$21 -> 47.090566 | V36: Total | X36: =SUM(X31:X35) -> 12 | Z36: =SUM(Z31:Z35) -> 49 | AB36: =$G$7*X36*'Vehicle Infos'!$L$29 -> 122.31
C37: Mobil Omnisport -Texaco Omnisport | D37: 12 | E37: 1 | F37: 8:13 | G37: 5 | I37: =$D$7*E37*'Vehicle Infos'!$L$10 -> 54.334751 | M37: Carrefour Monti - Hawai Escallier | N37: 18.5 | O37: 3 | P37: 7:47 | Q37: 13 | S37: =$F$7*O37*'Vehicle Infos'!$L$21 -> 40.363342
C38: Texaco Omnisport -Total Mfouda | D38: 14 | E38: 2 | F38: 8:22 | G38: 9 | I38: =$D$7*E38*'Vehicle Infos'!$L$10 -> 108.6695 | M38: Total | O38: =SUM(O31:O37) -> 18.5 | Q38: =SUM(Q32:Q37) -> 47 | S38: =$F$7*O38*'Vehicle Infos'!$L$21 -> 248.90728
C39: Total Mfouda-Mobil Elig-Essono | D39: 14.5 | E39: 0.5 | F39: 8:24 | G39: 2 | I39: =$D$7*E39*'Vehicle Infos'!$L$10 -> 27.167375
C40: Mobil Elig-Essono-Camair | D40: 15 | E40: 0.5 | F40: 8.25 | G40: 1 | I40: =$D$7*E40*'Vehicle Infos'!$L$10 -> 27.167375
C41: Total | E41: 15 | G41: =SUM(G32:G40) -> 55 | I41: =$D$7*E41*'Vehicle Infos'!$L$10 -> 815.02126
C44: Thursday 10:00-15:00 Scenario | M44: Thursday 10:00-15:00 Scenario | V44: Thursday 10:00-15:00 Scenario
C45: Soa-Yaounde: Road Network Stretches | D45: Cummulative distance (Km) | E45: Distance per stretch | F45: Clock Time | G45: Average time Taken (min) | H45: Tier 1 Emissions (kg CO2) (Daily) | I45: Tier 2 Emissions (kg CO2) (Daily) | M45: Mfou-Yaounde: Road Network Stretches | N45: Cummulative distance (Km) | O45: Distance per stretch | P45: Clock Time | Q45: Average time Taken (min) | R45: Tier 1 Emissions (kg CO2) (Daily) | S45: Tier 2 Emissions (kg CO2) (Daily) | V45: Mbankomo-Yaounde: Road Network Stretches | W45: Cummulative distance (Km) | X45: Distance per stretch | Y45: Clock Time | Z45: Average time Taken (min) | AA45: Tier 1 Emissions (kg CO2) (Daily) | AB45: Tier 2 Emissions (kg CO2) (Daily)
C46: Soa Centre | D46: 0 | E46: 0 | F46: 10.00 | H46: =D8*D3*'Vehicle Infos'!K10 -> 2734.8 | I46: =$D$8*E46*'Vehicle Infos'!$L$10 -> 0 | M46: Marche Mfou | N46: 0 | O46: 0 | P46: 10:15 | R46: =F8*F3*'Vehicle Infos'!K21 -> 909.96345 | S46: =$F$8*O46*'Vehicle Infos'!$L$21 -> 0 | V46: Green oil | W46: 0 | X46: 0 | Y46: 10:0 | Z46: 0 | AA46: =G8*G3*'Vehicle Infos'!K29 -> 411.84 | AB46: =$G$8*X46*'Vehicle Infos'!$L$29 -> 0
C47: Soa Centre -Vallée vert | D47: 7.5 | E47: 7.5 | F47: 10:07 | G47: 7 | I47: =$D$8*E47*'Vehicle Infos'!$L$10 -> 664.37752 | M47: Marche Mfou - Gare Mfou | N47: 1 | O47: 1 | P47: 10:17 | Q47: 2 | S47: =$F$8*O47*'Vehicle Infos'!$L$21 -> 15.818067 | V47: Green oil - Entrée Ngoumou | W47: 3 | X47: 3 | Y47: 10:5 | Z47: 5 | AB47: =$G$8*X47*'Vehicle Infos'!$L$29 -> 26.066066
...

Sheet Friday Est
D2: Soa | F2: Mfou | G2: Mbankomo
B3: Fuel consumed on total stretch | C3: Toyota | D3: 2.5 | F3: 3.3 | G3: 2.5 | H3: litres
C4: Mercedes | D4: 3 | H4: litres
B5: Number of buses | C5: Time frame | D5: Number of Vehicles
C6: 06:00 - 07:00 | D6: =25+14 -> 39 | F6: 14 | G6: 8
C7: 07:00 - 10:00 | D7: =98+60 -> 158 | F7: 74 | G7: 54
C8: 10:00 - 15:00 | D8: =153+101 -> 254 | F8: 85 | G8: 48
C9: 15:00 - 19:00 | D9: =96+53 -> 149 | F9: 83 | G9: 30
C10: 19:00 - 22:00 | D10: =87+32 -> 119 | F10: 25 | G10: 25
C11: Number of days in a year | D11: 365
C14: Friday 6:00-7:00 Scenario | H14: Daily Tail Pipe Emissions | L14: Friday 6:00-7:00 Scenario | U14: Friday 6:00-7:00 Scenario | AD14: Annual Tailpipe Emissions in kg CO2 (Tier 1)
C15: Soa-Yaounde: Road Network Stretches | D15: Cummulative distance (Km) | E15: Distance per stretch | F15: Clock Time | G15: Average time Taken (min) | H15: Tier 1 Emissions (kg CO2) (Daily) | I15: Tier 2 Emissions (kg CO2) (Daily) | L15: Mfou-Yaounde: Road Network Stretches | M15: Cummulative distance (Km) | N15: Distance per stretch | O15: Clock Time | P15: Average time Taken (min) | Q15: Tier 1 Emissions (kg CO2) (Daily) | R15: Tier 2 Emissions (kg CO2) (Daily) | U15: Mbankomo-Yaounde: Road Network Stretches | V15: Cummulative distance (Km) | W15: Distance per stretch | X15: Clock Time | Y15: Average time Taken (min) | Z15: Tier 1 Emissions (kg CO2) (Daily) | AA15: Tier 2 Emissions (kg CO2) (Daily) | AE15: 6:00 - 7:00 | AF15: 7:00 - 10:00 | AG15: 10:00 - 15:00 | AH15: 15:00 - 19:00 | AI15: 19:00 - 22:00 | AJ15: TOTAL
C16: Soa Centre | D16: 0 | E16: 0 | F16: 6:00 | G16: 0 | H16: =D6*D3*'Vehicle Infos'!K10 -> 310.05 | I16: =$D$6*E16*'Vehicle Infos'!$L$10 -> 0 | L16: Marche Mfou | M16: 0 | N16: 0 | O16: 6:00 | P16: 0 | Q16: =F6*F3*'Vehicle Infos'!K21 -> 146.4309 | R16: =$F$6*N16*'Vehicle Infos'!$L$21 -> 0 | U16: Green oil | V16: 0 | W16: 0 | X16: 6:00 | Y16: 0 | Z16: =G6*G3*'Vehicle Infos'!K29 -> 63.36 | AA16: =$G$6*W16*'Vehicle Infos'!$L$29 -> 0 | AD16: Friday | AE16: =SUM(H16:H25)*D11 -> 113168.25 | AF16: =SUM(H31:H40)*D11 -> 458476.5 | AG16: =SUM(H46:H55)*D11 -> 737044.5 | AH16: =SUM(H61:H70)*D11 -> 432360.75 | AI16: =SUM(H76:H85)*D11 -> 345308.25 | AJ16: =SUM(AE16:AI16) -> 2086358.2
C17: Soa Centre -Vallée vert | D17: 7.5 | E17: 7.5 | F17: 6:07 | G17: 7 | I17: =$D$6*E17*'Vehicle Infos'!$L$10 -> 75.32187 | L17: Marche Mfou - Gare Mfou | M17: 1 | N17: 1 | O17: 6:02 | P17: 2 | R17: =$F$6*N17*'Vehicle Infos'!$L$21 -> 2.545436 | U17: Green oil - Entrée Ngoumou | V17: 3 | W17: 3 | X17: 6:05 | Y17: 5 | AA17: =$G$6*W17*'Vehicle Infos'!$L$29 -> 4.010164
C18: Vallée vert -Petite marché | D18: 8 | E18: 0.5 | F18: 6:9 | G18: 2 | I18: =$D$6*E18*'Vehicle Infos'!$L$10 -> 5.021458 | L18: Gare Mfou - Gustave Eiffel | M18: 2.5 | N18: 1.5 | O18: 6:07 | P18: 5 | R18: =$F$6*N18*'Vehicle Infos'!$L$21 -> 3.818154 | U18: Entrée Ngoumou - Carrefour Nomayos | V18: 5.5 | W18: 2.5 | X18: 6:11 | Y18: 6 | AA18: =$G$6*W18*'Vehicle Infos'!$L$29 -> 3.3418033
C19: Petite marché-Eleveur | D19: 9 | E19: 1 | F19: 6:11 | G19: 2 | I19: =$D$6*E19*'Vehicle Infos'!$L$10 -> 10.042916 | L19: Gustave Eiffel - Entrée EP Meyo | M19: 9 | N19: 6.5 | O19: 6:16 | P19: 9 | R19: =$F$6*N19*'Vehicle Infos'!$L$21 -> 16.545334 | U19: Carrefour Nomayos - Entrée CIMENCAM | V19: 7.5 | W19: 2 | X19: 6:19 | Y19: 8 | AA19: =$G$6*W19*'Vehicle Infos'!$L$29 -> 2.6734427
C20: Eleveur-Total Ngoussou | D20: 10 | E20: 1 | F20: 6:14 | G20: 3 | I20: =$D$6*E20*'Vehicle Infos'!$L$10 -> 10.042916 | L20: Entrée EP Meyo - Carrefour Nkongoa | M20: 12 | N20: 3 | O20: 6:20 | P20: 4 | R20: =$F$6*N20*'Vehicle Infos'!$L$21 -> 7.636308 | U20: Entrée CIMENCAM - Barrier (Tradex Ahala) | V20: 12 | W20: 4.5 | X20: 6:32 | Y20: 13 | AA20: =$G$6*W20*'Vehicle Infos'!$L$29 -> 6.015246
C21: Total Ngoussou -Mobil Omnisport | D21: 11 | E21: 1 | F21: 6:20 | G21: 6 | I21: =$D$6*E21*'Vehicle Infos'!$L$10 -> 10.042916 | L21: Carrefour Nkongoa - Carrefour Monti | M21: 15.5 | N21: 3.5 | O21: 6:25 | P21: 5 | R21: =$F$6*N21*'Vehicle Infos'!$L$21 -> 8.909026 | U21: Total | W21: =SUM(W16:W20) -> 12 | Y21: =SUM(Y16:Y20) -> 32 | AA21: =$G$6*W21*'Vehicle Infos'!$L$29 -> 16.040656
C22: Mobil Omnisport -Texaco Omnisport | D22: 12 | E22: 1 | F22: 6:23 | G22: 3 | I22: =$D$6*E22*'Vehicle Infos'!$L$10 -> 10.042916 | L22: Carrefour Monti - Hawai Escallier | M22: 18.5 | N22: 3 | O22: 6:30 | P22: 5 | R22: =$F$6*N22*'Vehicle Infos'!$L$21 -> 7.636308
C23: Texaco Omnisport -Total Mfouda | D23: 14 | E23: 2 | F23: 6:27 | G23: 4 | I23: =$D$6*E23*'Vehicle Infos'!$L$10 -> 20.085832 | L23: Total | N23: =SUM(N16:N22) -> 18.5 | P23: =SUM(P17:P22) -> 30 | R23: =$F$6*N23*'Vehicle Infos'!$L$21 -> 47.090566
C24: Total Mfouda-Mobil Elig-Essono | D24: 14.5 | E24: 0.5 | F24: 6:29 | G24: 2 | I24: =$D$6*E24*'Vehicle Infos'!$L$10 -> 5.021458
C25: Mobil Elig-Essono-Camair | D25: 15 | E25: 0.5 | F25: 6:30 | G25: 1 | I25: =$D$6*E25*'Vehicle Infos'!$L$10 -> 5.021458
C26: Total | E26: 15 | G26: =SUM(G17:G25) -> 30 | I26: =$D$6*E26*'Vehicle Infos'!$L$10 -> 150.64374
C29: Friday 7:00-10:00 Scenario | L29: Friday 7:00-10:00 Scenario | U29: Friday 7:00-10:00 Scenario
C30: Soa-Yaounde: Road Network Stretches | D30: Cummulative distance (Km) | E30: Distance per stretch | F30: Clock Time | G30: Average time Taken (min) | H30: Tier 1 Emissions (kg CO2) (Daily) | I30: Tier 2 Emissions (kg CO2) (Daily) | L30: Mfou-Yaounde: Road Network Stretches | M30: Cummulative distance (Km) | N30: Distance per stretch | O30: Clock Time | P30: Average time Taken (min) | Q30: Tier 1 Emissions (kg CO2) (Daily) | R30: Tier 2 Emissions (kg CO2) (Daily) | U30: Mbankomo-Yaounde: Road Network Stretches | V30: Cummulative distance (Km) | W30: Distance per stretch | X30: Clock Time | Y30: Average time Taken (min) | Z30: Tier 1 Emissions (kg CO2) (Daily) | AA30: Tier 2 Emissions (kg CO2) (Daily)
C31: Soa Centre | D31: 0 | E31: 0 | F31: 7:30 | H31: =D7*D3*'Vehicle Infos'!K10 -> 1256.1 | I31: =$D$7*E31*'Vehicle Infos'!$L$10 -> 0 | L31: Marche Mfou | M31: 0 | N31: 0 | O31: 7:00 | P31: 0 | Q31: =F7*F3*'Vehicle Infos'!K21 -> 773.9919 | R31: =$F$7*N31*'Vehicle Infos'!$L$21 -> 0 | U31: Green oil | V31: 0 | W31: 0 | X31: 7:00 | Y31: 0 | Z31: =G7*G3*'Vehicle Infos'!K29 -> 427.68 | AA31: =$G$7*W31*'Vehicle Infos'!$L$29 -> 0
C32: Soa Centre -Vallée vert | D32: 7.5 | E32: 7.5 | F32: 7:37 | G32: 7 | I32: =$D$7*E32*'Vehicle Infos'!$L$10 -> 305.15014 | L32: Marche Mfou - Gare Mfou | M32: 1 | N32: 1 | O32: 7:02 | P32: 2 | R32: =$F$7*N32*'Vehicle Infos'!$L$21 -> 13.454447 | U32: Green oil - Entrée Ngoumou | V32: 3 | W32: 3 | X32: 7:05 | Y32: 5 | AA32: =$G$7*W32*'Vehicle Infos'!$L$29 -> 27.068607
C33: Vallée vert -Petite marché | D33: 8 | E33: 0.5 | F33: 7:40 | G33: 3 | I33: =$D$7*E33*'Vehicle Infos'!$L$10 -> 20.343343 | L33: Gare Mfou - Gustave Eiffel | M33: 2.5 | N33: 1.5 | O33: 7:07 | P33: 5 | R33: =$F$7*N33*'Vehicle Infos'!$L$21 -> 20.181671 | U33: Entrée Ngoumou - Carrefour Nomayos | V33: 5.5 | W33: 2.5 | X33: 7:12 | Y33: 7 | AA33: =$G$7*W33*'Vehicle Infos'!$L$29 -> 22.557173
C34: Petite marché-Eleveur | D34: 9 | E34: 1 | F34: 7:46 | G34: 6 | I34: =$D$7*E34*'Vehicle Infos'!$L$10 -> 40.686685 | L34: Gustave Eiffel - Entrée EP Meyo | M34: 9 | N34: 6.5 | O34: 7:17 | P34: 10 | R34: =$F$7*N34*'Vehicle Infos'!$L$21 -> 87.453908 | U34: Carrefour Nomayos - Entrée CIMENCAM | V34: 7.5 | W34: 2 | X34: 7:23 | Y34: 11 | AA34: =$G$7*W34*'Vehicle Infos'!$L$29 -> 18.045738
